Workbook

Sheet FeederMaster
A1: AssetCode | B1: CircleName | C1: DivisionName | D1: GssName | E1: FeederName | F1: FeederRating(A) | G1: VoltageRating(kV) | H1: FeederType | I1: FeederCode
A2: NES51012 | B2: KEONJHAR | C2: AED, Anandpur | D2: 132/33 KV ANANDPUR | E2: 33 KV GHASIPURA FDR. | F2: 285 | G2: 33 | H2: Non-Priority | I2: 46207420003
A3: NES51018 | B3: KEONJHAR | C3: AED, Anandpur | D3: 132/33 KV ANANDPUR | E3: 33KV BUS COUPLER | F3: 1 | G3: 33 | H3: Non-Priority | I3: ANAND_BC01
A4: NES51019 | B4: KEONJHAR | C4: AED, Anandpur | D4: 132/33 KV ANANDPUR | E4: 33 KV ANANDPUR FDR. | F4: 285 | G4: 33 | H4: Priority | I4: 46207420001
A5: NES51023 | B5: KEONJHAR | C5: AED, Anandpur | D5: 132/33 KV ANANDPUR | E5: 33 KV RAMACHANDRAPUR FDR. | F5: 279 | G5: 33 | H5: Non-Priority | I5: 46207420004
A6: NES82729 | B6: BARIPADA | C6: UED, Udala | D6: 132/33 KV UDALA | E6: 33 KV UDALA | F6: 444 | G6: 33 | H6: Non-Priority | I6: 45207412004
A7: NES82730 | B7: BALASORE | C7: CED, Balasore | D7: 132/33 KV UDALA | E7: 33 KV BERHAMPUR | F7: 279 | G7: 33 | H7: Non-Priority | I7: 45207412001
A8: NES82775 | B8: BARIPADA | C8: BPED, Baripada | D8: 132/33 KV BETNOTI | E8: 33 KV BADSHAI FDR. | F8: 444 | G8: 33 | H8: Non-Priority | I8: 45207409001
A9: NES82800 | B9: BARIPADA | C9: BPED, Baripada | D9: 132/33 KV BETNOTI | E9: 33 KV BETNOTI FDR. | F9: 285 | G9: 33 | H9: Non-Priority | I9: 45207409002
A10: NES82812 | B10: BARIPADA | C10: UED, Udala | D10: 132/33 KV UDALA | E10: 33 KV KHUNTA | F10: 444 | G10: 33 | H10: Priority | I10: 45207412003
A11: NES82813 | B11: BARIPADA | C11: UED, Udala | D11: 132/33 KV UDALA | E11: 33KV BUS COUPLER | F11: 1 | G11: 33 | H11: Non-Priority | I11: UDALA_BC01
A12: NES82817 | B12: BALASORE | C12: JED, Jaleswar | D12: 132/33 KV JALESWAR | E12: 33 KV JALESWAR FDR. | F12: 279 | G12: 33 | H12: Priority | I12: 43207404003
A13: NES82818 | B13: BALASORE | C13: JED, Jaleswar | D13: 132/33 KV JALESWAR | E13: 33 KV HATIGARH FDR. | F13: 248 | G13: 33 | H13: Non-Priority | I13: 43207404001
A14: NES82825 | B14: BARIPADA | C14: UED, Udala | D14: 132/33 KV UDALA | E14: 33 KV KAPTIPADA | F14: 4 | G14: 33 | H14: Non-Priority | I14: 45207412005
A15: NES83187 | B15: KEONJHAR | C15: AED, Anandpur | D15: 132/33 KV AGARPADA | E15: 33 KV BISALPATA FDR. | F15: 444 | G15: 33 | H15: Non-Priority | I15: 44207413001
A16: NES83197 | B16: KEONJHAR | C16: AED, Anandpur | D16: 132/33 KV ANANDPUR | E16: 33 KV CHHENAPADI FDR. | F16: 285 | G16: 33 | H16: Non-Priority | I16: 46207420002
A17: NES83202 | B17: BARIPADA | C17: BPED, Baripada | D17: 132/33 KV BETNOTI | E17: 33KV BUS COUPLER | F17: 1 | G17: 33 | H17: Non-Priority | I17: BETNO_BC01
A18: NES83204 | B18: KEONJHAR | C18: KED, Keonjhar | D18: 220/33 KV KEONJHAR RANKI GIS | E18: 33KV KEONJHAR-I FDR. | F18: 444 | G18: 33 | H18: Priority | I18: 46280424002
A19: NES83206 | B19: KEONJHAR | C19: AED, Anandpur | D19: 132/33 KV DHENKIKOTE / TIKIRA | E19: 33 KV HARICHANDANPUR FDR. | F19: 285 | G19: 33 | H19: Non-Priority | I19: 46207422003
A20: NES83208 | B20: BARIPADA | C20: BPED, Baripada | D20: 132/33 BARIPADA | E20: 33 KV RAGHUNATHPUR FDR. | F20: 285 | G20: 33 | H20: Priority | I20: 45207408005
A21: NES83212 | B21: KEONJHAR | C21: AED, Anandpur | D21: 132/33 KV AGARPADA | E21: 33 KV CHHAYAL SINGH FDR. | F21: 444 | G21: 33 | H21: Non-Priority | I21: 44207413002
A22: NES83213 | B22: KEONJHAR | C22: JOED, Joda | D22: 220/132/33 KV JODA | E22: 33 KV BILEIPADA FDR. | F22: 285 | G22: 33 | H22: Non-Priority | I22: 46287423002
A23: NES83217 | B23: JAJPUR | C23: JRED, Jajpur Road | D23: 132/33 KV JAJPUR ROAD | E23: 33 KV SALAKANA FDR. | F23: 444 | G23: 33 | H23: Non-Priority | I23: 46107418005
A24: NES83221 | B24: KEONJHAR | C24: KED, Keonjhar | D24: 220/33 KV KEONJHAR RANKI GIS | E24: 33 KV JUDIA | F24: 444 | G24: 33 | H24: Priority | I24: 46280424001
A25: NES83226 | B25: KEONJHAR | C25: AED, Anandpur | D25: 132/33 KV DHENKIKOTE / TIKIRA | E25: 33KV BUS COUPLER | F25: 1 | G25: 33 | H25: Non-Priority | I25: TIKIR_BC01
A26: NES83229 | B26: KEONJHAR | C26: AED, Anandpur | D26: 132/33 KV DHENKIKOTE / TIKIRA | E26: 33 KV DHENKIKOTE FDR. | F26: 285 | G26: 33 | H26: Non-Priority | I26: 46207422001
A27: NES83234 | B27: BARIPADA | C27: RED, Rairangpur | D27: 132/33 KV KARANJIA | E27: 33 KV KARANJIA FDR. | F27: 279 | G27: 33 | H27: Non-Priority | I27: 45207410002
A28: NES83235 | B28: BARIPADA | C28: RED, Rairangpur | D28: 132/33 KV KARANJIA | E28: 33 KV JASHIPUR FDR. | F28: 279 | G28: 33 | H28: Priority | I28: 45207410001
A29: NES83241 | B29: BALASORE | C29: JED, Jaleswar | D29: 132/33 KV BHOGRAI | E29: 33KV BUS COUPLER | F29: 1 | G29: 33 | H29: Non-Priority | I29: BHOGR_BC01
A30: NES83242 | B30: KEONJHAR | C30: KED, Keonjhar | D30: 220/33 KV KEONJHAR RANKI GIS | E30: 33 KV MEDICAL FDR. | F30: 53 | G30: 33 | H30: Non-Priority | I30: 46280424004
A31: NES83248 | B31: BARIPADA | C31: BPED, Baripada | D31: 132/33 KV BETNOTI | E31: 33 KV BETNOTI - II FDR. | F31: 444 | G31: 33 | H31: Non-Priority | I31: 45207409004
A32: NES83252 | B32: BALASORE | C32: JED, Jaleswar | D32: 132/33 KV BHOGRAI | E32: 33KV KAMARDA NEW FEEDER | F32: 279 | G32: 33 | H32: Non-Priority | I32: 43207403002
A33: NES83253 | B33: BHADRAK | C33: BNED, Bhadrak | D33: 132/33 KV CHANDABALI | E33: 33 KV JASHIPUR (CHANDABALI ) FDR. | F33: 285 | G33: 33 | H33: Non-Priority | I33: 44207415002
A34: NES83255 | B34: KEONJHAR | C34: AED, Anandpur | D34: 132/33 KV AGARPADA | E34: 33KV BUS COUPLER | F34: 1 | G34: 33 | H34: Non-Priority | I34: AGARP_BC01
A35: NES83256 | B35: KEONJHAR | C35: KED, Keonjhar | D35: 220/33 KV KEONJHAR RANKI GIS | E35: 33 KV KEONJHAR 3 (NARANPUR) | F35: 444 | G35: 33 | H35: Non-Priority | I35: 46280424003
A36: NES83261 | B36: BALASORE | C36: JED, Jaleswar | D36: 132/33 KV BHOGRAI | E36: 33 KV BHOGRAI FDR. | F36: 444 | G36: 33 | H36: Non-Priority | I36: 43207403001
A37: NES83265 | B37: KEONJHAR | C37: AED, Anandpur | D37: 132/33 KV DHENKIKOTE / TIKIRA | E37: 33 KV GHATAGAON FDR. | F37: 285 | G37: 33 | H37: Non-Priority | I37: 46207422002
A38: NSC95199 | B38: BALASORE | C38: JED, Jaleswar | D38: 132/33 KV JALESWAR | E38: 33 KV KAMARDA FDR. | F38: 285 | G38: 33 | H38: Non-Priority | I38: 43207404004
A39: TPN60009 | B39: JAJPUR | C39: JRED, Jajpur Road | D39: 132/33 KV JAJPUR ROAD | E39: 33 KV KUAKHIA FDR. | F39: 444 | G39: 33 | H39: Priority | I39: 46107418003
A40: TPN60012 | B40: JAJPUR | C40: JRED, Jajpur Road | D40: 132/33 KV JAJPUR ROAD | E40: 33 KV JAJPUR ROAD FDR. | F40: 444 | G40: 33 | H40: Priority | I40: 46107418002
...

Sheet Sheet1
A1: Circle | B1: Division | C1: GSS | D1: Feeder | E1: Current carrying capacity (AMPs) | F1: Overload alert setting
A2: BALASORE | B2: BED, Balasore | C2: 132/33 KV CHANDIPUR | D2: 33 KV SWADHINPADIA FDR. | E2: 468 | F2: 374.4 | G2: =SUMIFS(FeederMaster!F:F,FeederMaster!E:E,Sheet1!D2) -> 0 | H2: =F2/E2 -> 0.8 | I2: =E2*0.95 -> 444.6
A3: BALASORE | B3: BED, Balasore | C3: 132/33 KV CHANDIPUR | D3: 33 KV ITR FEEDER | F3: 0 | G3: =SUMIFS(FeederMaster!F:F,FeederMaster!E:E,Sheet1!D3) -> 106 | H3: =F3/E3 -> #DIV/0!
A4: BALASORE | B4: BED, Balasore | C4: 132/33 KV CHANDIPUR | D4: 33 KV SARAGAON FDR. | E4: 189 | F4: 151.2 | G4: =SUMIFS(FeederMaster!F:F,FeederMaster!E:E,Sheet1!D4) -> 0 | H4: =F4/E4 -> 0.8
A5: BALASORE | B5: BED, Balasore | C5: 220/132/33 KV BALASORE | D5: 33 KV MEDICAL FEEDER | E5: 395 | F5: 316 | G5: =SUMIFS(FeederMaster!F:F,FeederMaster!E:E,Sheet1!D5) -> 53 | H5: =F5/E5 -> 0.8
A6: BALASORE | B6: BED, Balasore | C6: 220/132/33 KV BALASORE | D6: 33KV BALASORE -2 FDR. | E6: 395 | F6: 316 | G6: =SUMIFS(FeederMaster!F:F,FeederMaster!E:E,Sheet1!D6) -> 376 | H6: =F6/E6 -> 0.8
A7: BALASORE | B7: BED, Balasore | C7: 220/132/33 KV BALASORE | D7: 33KV BALASORE NO. 1 FDR. | E7: 300 | F7: 240 | G7: =SUMIFS(FeederMaster!F:F,FeederMaster!E:E,Sheet1!D7) -> 285 | H7: =F7/E7 -> 0.8
A8: BALASORE | B8: BED, Balasore | C8: 220/132/33 KV BALASORE | D8: 33KV CHANDIPUR FDR. | E8: 468 | F8: 374.4 | G8: =SUMIFS(FeederMaster!F:F,FeederMaster!E:E,Sheet1!D8) -> 444 | H8: =F8/E8 -> 0.8
A9: BALASORE | B9: BED, Balasore | C9: 220/132/33 KV BALASORE | D9: 33KV CITY FDR. | E9: 395 | F9: 316 | G9: =SUMIFS(FeederMaster!F:F,FeederMaster!E:E,Sheet1!D9) -> 376 | H9: =F9/E9 -> 0.8
A10: BALASORE | B10: BTED, Basta | C10: 132/33 KV BASTA | D10: 33 KV BALIAPAL FDR. | E10: 293 | F10: 234 | G10: =SUMIFS(FeederMaster!F:F,FeederMaster!E:E,Sheet1!D10) -> 279 | H10: =F10/E10 -> 0.79863481
A11: BALASORE | B11: BTED, Basta | C11: 132/33 KV BASTA | D11: 33 KV BASTA FDR. | E11: 293 | F11: 234 | G11: =SUMIFS(FeederMaster!F:F,FeederMaster!E:E,Sheet1!D11) -> 279 | H11: =F11/E11 -> 0.79863481
A12: BALASORE | B12: BTED, Basta | C12: 132/33 KV BASTA | D12: 33 KV JAMASULI FDR. | E12: 300 | F12: 240 | G12: =SUMIFS(FeederMaster!F:F,FeederMaster!E:E,Sheet1!D12) -> 285 | H12: =F12/E12 -> 0.8
A13: BALASORE | B13: BTED, Basta | C13: 132/33 KV BASTA | D13: 33 KV RAJGHAT FDR. | E13: 300 | F13: 240 | G13: =SUMIFS(FeederMaster!F:F,FeederMaster!E:E,Sheet1!D13) -> 285 | H13: =F13/E13 -> 0.8
A14: BALASORE | B14: CED, Balasore | C14: 132/33 KV SOMNATHPUR | D14: 33 KV HIL FDR.[HT CONSUMER] | F14: 0 | G14: =SUMIFS(FeederMaster!F:F,FeederMaster!E:E,Sheet1!D14) -> 15 | H14: =F14/E14 -> #DIV/0!
A15: BALASORE | B15: CED, Balasore | C15: 132/33 KV SOMNATHPUR | D15: 33 KV NEW NILGIRI FDR. | E15: 468 | F15: 374.4 | G15: =SUMIFS(FeederMaster!F:F,FeederMaster!E:E,Sheet1!D15) -> 444 | H15: =F15/E15 -> 0.8
A16: BALASORE | B16: CED, Balasore | C16: 132/33 KV SOMNATHPUR | D16: 33 KV NOCCI FDR. | E16: 261 | F16: 208.8 | G16: =SUMIFS(FeederMaster!F:F,FeederMaster!E:E,Sheet1!D16) -> 248 | H16: =F16/E16 -> 0.8
A17: BALASORE | B17: CED, Balasore | C17: 132/33 KV UDALA | D17: 33 KV BERHAMPUR | E17: 293 | F17: 234 | G17: =SUMIFS(FeederMaster!F:F,FeederMaster!E:E,Sheet1!D17) -> 279 | H17: =F17/E17 -> 0.79863481
A18: BALASORE | B18: CED, Balasore | C18: 220/132/33 KV BALASORE | D18: 33KV BALGOPALPUR FDR. | E18: 293 | F18: 234 | G18: =SUMIFS(FeederMaster!F:F,FeederMaster!E:E,Sheet1!D18) -> 279 | H18: =F18/E18 -> 0.79863481
A19: BALASORE | B19: CED, Balasore | C19: 220/132/33 KV BALASORE | D19: 33KV EMAMI / MITRAPUR FDR. | E19: 468 | F19: 374.4 | G19: =SUMIFS(FeederMaster!F:F,FeederMaster!E:E,Sheet1!D19) -> 444 | H19: =F19/E19 -> 0.8
A20: BALASORE | B20: CED, Balasore | C20: 220/132/33 KV BALASORE | D20: 33KV NILAGIRI FDR. | E20: 293 | F20: 234 | G20: =SUMIFS(FeederMaster!F:F,FeederMaster!E:E,Sheet1!D20) -> 279 | H20: =F20/E20 -> 0.79863481
A21: BALASORE | B21: CED, Balasore | C21: 220/132/33 KV BALASORE | D21: 33KV ODANGI FDR. | E21: 293 | F21: 234 | G21: =SUMIFS(FeederMaster!F:F,FeederMaster!E:E,Sheet1!D21) -> 279 | H21: =F21/E21 -> 0.79863481
A22: BALASORE | B22: CED, Balasore | C22: 220/132/33 KV BALASORE | D22: 33KV RUPSA FDR. | E22: 261 | F22: 208.8 | G22: =SUMIFS(FeederMaster!F:F,FeederMaster!E:E,Sheet1!D22) -> 248 | H22: =F22/E22 -> 0.8
A23: BALASORE | B23: CED, Balasore | C23: 220/132/33 KV BALASORE | D23: 33KV SRIJANG FDR. | E23: 189 | F23: 151.2 | G23: =SUMIFS(FeederMaster!F:F,FeederMaster!E:E,Sheet1!D23) -> 179 | H23: =F23/E23 -> 0.8
A24: BALASORE | B24: JED, Jaleswar | C24: 132/33 KV BHOGRAI | D24: 33 KV BHOGRAI FDR. | E24: 468 | F24: 374.4 | G24: =SUMIFS(FeederMaster!F:F,FeederMaster!E:E,Sheet1!D24) -> 444 | H24: =F24/E24 -> 0.8
A25: BALASORE | B25: JED, Jaleswar | C25: 132/33 KV BHOGRAI | D25: 33KV KAMARDA NEW FEEDER | E25: 293 | F25: 234 | G25: =SUMIFS(FeederMaster!F:F,FeederMaster!E:E,Sheet1!D25) -> 279 | H25: =F25/E25 -> 0.79863481
A26: BALASORE | B26: JED, Jaleswar | C26: 132/33 KV JALESWAR | D26: 33 KV BARTANA FDR. | E26: 300 | F26: 240 | G26: =SUMIFS(FeederMaster!F:F,FeederMaster!E:E,Sheet1!D26) -> 285 | H26: =F26/E26 -> 0.8
... A43: BARIPADA | B43: BPED, Baripada | C43: 132/33 KV BARIPADA | D43: 33 KV SAMAKHUNTA FDR. | E43: 261 | F43: 208.8 | G43: =SUMIFS(FeederMaster!F:F,FeederMaster!E:E,Sheet1!D43) -> 248 | H43: =F43/E43 -> 0.8
A44: BARIPADA | B44: BPED, Baripada | C44: 132/33 KV BARIPADA | D44: 33 KV SOLAR PLANT FDR. | F44: 0 | G44: =SUMIFS(FeederMaster!F:F,FeederMaster!E:E,Sheet1!D44) -> 15 | H44: =F44/E44 -> #DIV/0!
A45: BARIPADA | B45: BPED, Baripada | C45: 132/33 KV BARIPADA | D45: 33KV STADIUM FEEDER | E45: 468 | F45: 374.4 | G45: =SUMIFS(FeederMaster!F:F,FeederMaster!E:E,Sheet1!D45) -> 444 | H45: =F45/E45 -> 0.8
A46: BARIPADA | B46: BPED, Baripada | C46: 132/33 KV BETNOTI | D46: 33 KV BADSHAI FDR. | E46: 468 | F46: 374.4 | G46: =SUMIFS(FeederMaster!F:F,FeederMaster!E:E,Sheet1!D46) -> 444 | H46: =F46/E46 -> 0.8
A47: BARIPADA | B47: BPED, Baripada | C47: 132/33 KV BETNOTI | D47: 33 KV BETNOTI - II FDR. | E47: 468 | F47: 374.4 | G47: =SUMIFS(FeederMaster!F:F,FeederMaster!E:E,Sheet1!D47) -> 444 | H47: =F47/E47 -> 0.8
A48: BARIPADA | B48: BPED, Baripada | C48: 132/33 KV BETNOTI | D48: 33 KV BETNOTI FDR. | E48: 300 | F48: 240 | G48: =SUMIFS(FeederMaster!F:F,FeederMaster!E:E,Sheet1!D48) -> 285 | H48: =F48/E48 -> 0.8
A49: BARIPADA | B49: RED, Rairangpur | C49: 132/33 KV KARANJIA | D49: 33 KV JASHIPUR FDR. | E49: 293 | F49: 234 | G49: =SUMIFS(FeederMaster!F:F,FeederMaster!E:E,Sheet1!D49) -> 279 | H49: =F49/E49 -> 0.79863481
A50: BARIPADA | B50: RED, Rairangpur | C50: 132/33 KV KARANJIA | D50: 33 KV KARANJIA FDR. | E50: 293 | F50: 234 | G50: =SUMIFS(FeederMaster!F:F,FeederMaster!E:E,Sheet1!D50) -> 279 | H50: =F50/E50 -> 0.79863481
A51: BARIPADA | B51: RED, Rairangpur | C51: 132/33 KV KARANJIA | D51: 33 KV SUKURULI FDR. | E51: 468 | F51: 374.4 | G51: =SUMIFS(FeederMaster!F:F,FeederMaster!E:E,Sheet1!D51) -> 444 | H51: =F51/E51 -> 0.8
A52: BARIPADA | B52: RED, Rairangpur | C52: 132/33 KV RAIRANGPUR | D52: 33 KV BAHALDA FDR. | E52: 261 | F52: 208.8 | G52: =SUMIFS(FeederMaster!F:F,FeederMaster!E:E,Sheet1!D52) -> 248 | H52: =F52/E52 -> 0.8
A53: BARIPADA | B53: RED, Rairangpur | C53: 132/33 KV RAIRANGPUR | D53: 33 KV BISOI FDR. | E53: 293 | F53: 234 | G53: =SUMIFS(FeederMaster!F:F,FeederMaster!E:E,Sheet1!D53) -> 279 | H53: =F53/E53 -> 0.79863481
A54: BARIPADA | B54: RED, Rairangpur | C54: 132/33 KV RAIRANGPUR | D54: 33 KV GORUMAHISANI FDR. | E54: 300 | F54: 240 | G54: =SUMIFS(FeederMaster!F:F,FeederMaster!E:E,Sheet1!D54) -> 285 | H54: =F54/E54 -> 0.8
A55: BARIPADA | B55: RED, Rairangpur | C55: 132/33 KV RAIRANGPUR | D55: 33 KV KUSUMI FDR. | E55: 261 | F55: 208.8 | G55: =SUMIFS(FeederMaster!F:F,FeederMaster!E:E,Sheet1!D55) -> 248 | H55: =F55/E55 -> 0.8
A56: BARIPADA | B56: RED, Rairangpur | C56: 132/33 KV RAIRANGPUR | D56: 33 KV RAIRANGPUR FDR. | E56: 261 | F56: 208.8 | G56: =SUMIFS(FeederMaster!F:F,FeederMaster!E:E,Sheet1!D56) -> 248 | H56: =F56/E56 -> 0.8
...
